Workbook
Name Slicer_Product: #N/A

Sheet Revenue by Product
A3: Row Labels | B3: Sum of Revenue (£)
A4: Laptop | B4: 35700
A5: Grand Total | B5: 35700
A29: Format Pivot Chart Data Labels as £

Sheet Revenue by City
A3: City | B3: Product | C3: Sum of Units | D3: Sum of Revenue (£)
A4: Bristol | B4: Laptop | C4: 12 | D4: 10200
A5: Bristol Total | C5: 12 | D5: 10200
A6: London | B6: Laptop | C6: 12 | D6: 10200
A7: London Total | C7: 12 | D7: 10200
A8: Oxford | B8: Laptop | C8: 4 | D8: 3400
A9: Oxford Total | C9: 4 | D9: 3400
A10: Reading | B10: Laptop | C10: 14 | D10: 11900
A11: Reading Total | C11: 14 | D11: 11900
A12: Grand Total | C12: 42 | D12: 35700

Sheet City Revenue Pivot Table
A3: Row Labels | B3: Sum of Revenue (£)
A4: Bristol | B4: 10200
A5: London | B5: 10200
A6: Oxford | B6: 3400
A7: Reading | B7: 11900
A8: Grand Total | B8: 35700

Sheet Sales Dashboard.
B1: Total Revenue | C1: ='KPI Revenue'!A4 -> 35700 | E1: Total Orders | F1: ='KPI Revenue'!B4 -> 12 | H1: Total Units Sold | I1: ='KPI Revenue'!C4 -> 42

Sheet KPI Revenue
A3: Sum of Revenue (£) | B3: Count of Order ID | C3: Sum of Units
A4: 35700 | B4: 12 | C4: 42
A10: Connect your Dashboard KPI to cell A4

Sheet Sales Data
A1: Order ID | B1: Date | C1: Month | D1: City | E1: Product | F1: Units | G1: Unit Price (£) | H1: Revenue (£) | I1: Sales Performance
A2: ORD-001 | B2: 46025 | C2: 46023 | D2: Oxford | E2: Mouse | F2: 3 | G2: 25 | H2: =F2*G2 -> 75 | I2: =IF(H2>=1000,"High Sales","Low Sales") -> Low Sales
A3: ORD-002 | B3: 46027 | C3: 46023 | D3: Bristol | E3: Keyboard | F3: 4 | G3: 40 | H3: =F3*G3 -> 160 | I3: =IF(H3>=1000,"High Sales","Low Sales") -> Low Sales
A4: ORD-003 | B4: 46029 | C4: 46023 | D4: Reading | E4: Laptop | F4: 5 | G4: 850 | H4: =F4*G4 -> 4250 | I4: =IF(H4>=1000,"High Sales","Low Sales") -> High Sales
A5: ORD-004 | B5: 46031 | C5: 46023 | D5: London | E5: Monitor | F5: 6 | G5: 220 | H5: =F5*G5 -> 1320 | I5: =IF(H5>=1000,"High Sales","Low Sales") -> High Sales
A6: ORD-005 | B6: 46033 | C6: 46023 | D6: Oxford | E6: Headphones | F6: 1 | G6: 65 | H6: =F6*G6 -> 65 | I6: =IF(H6>=1000,"High Sales","Low Sales") -> Low Sales
A7: ORD-006 | B7: 46035 | C7: 46023 | D7: Bristol | E7: Mouse | F7: 2 | G7: 25 | H7: =F7*G7 -> 50 | I7: =IF(H7>=1000,"High Sales","Low Sales") -> Low Sales
A8: ORD-007 | B8: 46037 | C8: 46023 | D8: Reading | E8: Keyboard | F8: 3 | G8: 40 | H8: =F8*G8 -> 120 | I8: =IF(H8>=1000,"High Sales","Low Sales") -> Low Sales
A9: ORD-008 | B9: 46039 | C9: 46023 | D9: London | E9: Laptop | F9: 4 | G9: 850 | H9: =F9*G9 -> 3400 | I9: =IF(H9>=1000,"High Sales","Low Sales") -> High Sales
A10: ORD-009 | B10: 46041 | C10: 46023 | D10: Oxford | E10: Monitor | F10: 5 | G10: 220 | H10: =F10*G10 -> 1100 | I10: =IF(H10>=1000,"High Sales","Low Sales") -> High Sales
A11: ORD-010 | B11: 46043 | C11: 46023 | D11: Bristol | E11: Headphones | F11: 6 | G11: 65 | H11: =F11*G11 -> 390 | I11: =IF(H11>=1000,"High Sales","Low Sales") -> Low Sales
A12: ORD-011 | B12: 46076 | C12: 46054 | D12: London | E12: Laptop | F12: 2 | G12: 850 | H12: =F12*G12 -> 1700 | I12: =IF(H12>=1000,"High Sales","Low Sales") -> High Sales
A13: ORD-012 | B13: 46078 | C13: 46054 | D13: Oxford | E13: Monitor | F13: 3 | G13: 220 | H13: =F13*G13 -> 660 | I13: =IF(H13>=1000,"High Sales","Low Sales") -> Low Sales
... A61: ORD-060 | B61: 46186 | C61: 46174 | D61: Oxford | E61: Headphones | F61: 1 | G61: 65 | H61: =F61*G61 -> 65 | I61: =IF(H61>=1000,"High Sales","Low Sales") -> Low Sales

Sheet retail_sales_project
A1: Calculate Total Sales Revenue using SUM
A2: Total Sales Revenue | B2: =SUM('Sales Data'!H2:H61) -> 50770
A5: Calculate Total Orders using COUNTA.
A6: Total Orders | B6: =COUNT('Sales Data'!H2:H61) -> 60
A9: Calculate Total Units Sold using SUM
A11: Total Units Sold | B11: =SUM('Sales Data'!F2:F61) -> 210
A14: Calculate Average Sales Revenue using AVERAGE
A16: Average Sales Revenue. | B16: =AVERAGE('Sales Data'!H2:H61) -> 846.16667
A19: Find the Highest Sales Revenue using MAX.
A21: Highest Order Revenue | B21: =MAX('Sales Data'!H2:H61) -> 5100
A24: Find the Lowest Sales Revenue using MIN
A26: Lowest Revenue | B26: =MIN('Sales Data'!H2:H61) -> 25
A29: Calculate London's Total Sales using SUMIF
A31: London Total Sales | B31: =SUMIF('Sales Data'!D2:D61,"London", 'Sales Data'!H2:H61) -> 15400
A34: Count London Orders using COUNTIF
A36: Total London Orders. | B36: =COUNTIF('Sales Data'!D2:D61,"London") -> 15
A39: Calculate Average London Sales using AVERAGEIF
A41: Average London Sales | B41: =AVERAGEIF('Sales Data'!D2:D61,"London",'Sales Data'!H2:H61) -> 1026.6667
A44: Calculate Total Laptop Sales using SUMIF
A46: Total Laptop Revenue | B46: =SUMIF('Sales Data'!E2:E61,"Laptop",'Sales Data'!H2:H61) -> 35700
A48: Count Total Laptop Orders using COUNTIF
A50: Total Laptop Orders | B50: =COUNTIF('Sales Data'!E2:E61,"Laptop") -> 12
A54: Calculate Total Laptop Units Sold
A56: Total Laptop Units Sold. | B56: =SUMIF('Sales Data'!E2:E61,"Laptop",'Sales Data'!F2:F61) -> 42
A59: Create the table headings
B61: Product | C61: Total Revenue (£) | D61: Total Orders | E61: Units Sold
B62: Laptop | C62: =SUMIF('Sales Data'!$E$2:$E$61,B62,'Sales Data'!$H$2:$H$61) -> 35700 | D62: =COUNTIF('Sales Data'!$E$2:$E$61,retail_sales_project!B62) -> 12 | E62: =SUMIF('Sales Data'!$E$2:$E$61,retail_sales_project!B62,'Sales Data'!F2:F61) -> 42
B63: Mouse | C63: =SUMIF('Sales Data'!$E$2:$E$61,B63,'Sales Data'!$H$2:$H$61) -> 950 | D63: =COUNTIF('Sales Data'!$E$2:$E$61,retail_sales_project!B63) -> 12 | E63: =SUMIF('Sales Data'!$E$2:$E$61,retail_sales_project!B63,'Sales Data'!F3:F62) -> 45
B64: Keyboard | C64: =SUMIF('Sales Data'!$E$2:$E$61,B64,'Sales Data'!$H$2:$H$61) -> 1840 | D64: =COUNTIF('Sales Data'!$E$2:$E$61,retail_sales_project!B64) -> 12 | E64: =SUMIF('Sales Data'!$E$2:$E$61,retail_sales_project!B64,'Sales Data'!F4:F63) -> 42
B65: Monitor | C65: =SUMIF('Sales Data'!$E$2:$E$61,B65,'Sales Data'!$H$2:$H$61) -> 9680 | D65: =COUNTIF('Sales Data'!$E$2:$E$61,retail_sales_project!B65) -> 12 | E65: =SUMIF('Sales Data'!$E$2:$E$61,retail_sales_project!B65,'Sales Data'!F5:F64) -> 38
B66: Headphones | C66: =SUMIF('Sales Data'!$E$2:$E$61,B66,'Sales Data'!$H$2:$H$61) -> 2600 | D66: =COUNTIF('Sales Data'!$E$2:$E$61,retail_sales_project!B66) -> 12 | E66: =SUMIF('Sales Data'!$E$2:$E$61,retail_sales_project!B66,'Sales Data'!F6:F65) -> 39
A70: How much revenue did we earn from Laptop sales in London?
A72: London Laptop Revenue | B72: =SUMIFS('Sales Data'!H2:H61,'Sales Data'!D2:D61,"London",'Sales Data'!E2:E61,"Laptop") -> 10200
A75: XLOOKUP
A77: Enter Order ID | B77: ORD-048 | C77: =_xlfn.XLOOKUP(B77,'Sales Data'!A2:A61,'Sales Data'!H2:H61,"Not Found") -> 150
B78: ORD-057 | C78: =_xlfn.XLOOKUP(B78,'Sales Data'!A2:A61,'Sales Data'!H2:H61,"Not Found") -> 160
B79: ORD-052 | C79: =_xlfn.XLOOKUP(B79,'Sales Data'!A3:A62,'Sales Data'!H3:H62,"Not Found") -> 200
A83: Find the Product Name using XLOOKUP
A85: Product Name | B85: ORD-052 | C85: =_xlfn.XLOOKUP(B85,'Sales Data'!A2:A61,'Sales Data'!E2:E61,"Not Found") -> Keyboard
B86: ORD-060 | C86: =_xlfn.XLOOKUP(B86,'Sales Data'!A2:A61,'Sales Data'!E2:E61,"Not Found") -> Headphones
...

Sheet EXcel formula
A1: Function | B1: Example question
A2: SUMIF | B2: What is total Laptop revenue?
A3: COUNTIF | B3: How many Laptop orders are there?
A4: SUMIFS | B4: What is total Laptop revenue in London?
A5: COUNTIFS | B5: How many Laptop orders are from London?

Sheet Analysis
A1: Sales summary | B1: Value | D1: Product | E1: Revenue (£)
A2: Total revenue | B2: =SUM('Sales Data'!H2:H61) -> 50770 | D2: Laptop | E2: =SUMIF('Sales Data'!E$2:E$61,D2,'Sales Data'!H$2:H$61) -> 35700
A3: Total orders | B3: =COUNTA('Sales Data'!A2:A61) -> 60 | D3: Headphones | E3: =SUMIF('Sales Data'!E$2:E$61,D3,'Sales Data'!H$2:H$61) -> 2600
A4: Total units | B4: =SUM('Sales Data'!F2:F61) -> 210 | D4: Keyboard | E4: =SUMIF('Sales Data'!E$2:E$61,D4,'Sales Data'!H$2:H$61) -> 1840
A5: Average order revenue | B5: =B2/B3 -> 846.16667 | D5: Monitor | E5: =SUMIF('Sales Data'!E$2:E$61,D5,'Sales Data'!H$2:H$61) -> 9680
A6: Highest-value order | B6: =MAX('Sales Data'!H2:H61) -> 5100 | D6: Mouse | E6: =SUMIF('Sales Data'!E$2:E$61,D6,'Sales Data'!H$2:H$61) -> 950
A9: Month | B9: Revenue (£)
A10: 46023 | B10: =SUMIF('Sales Data'!C$2:C$61,A10,'Sales Data'!H$2:H$61) -> 10930
A11: 46054 | B11: =SUMIF('Sales Data'!C$2:C$61,A11,'Sales Data'!H$2:H$61) -> 4770
A12: 46082 | B12: =SUMIF('Sales Data'!C$2:C$61,A12,'Sales Data'!H$2:H$61) -> 8660
A13: 46113 | B13: =SUMIF('Sales Data'!C$2:C$61,A13,'Sales Data'!H$2:H$61) -> 7550
A14: 46143 | B14: =SUMIF('Sales Data'!C$2:C$61,A14,'Sales Data'!H$2:H$61) -> 7240
A15: 46174 | B15: =SUMIF('Sales Data'!C$2:C$61,A15,'Sales Data'!H$2:H$61) -> 11620

Sheet Prompt Practice
A1: Step | B1: Skill | C1: Try this prompt | D1: How to verify
A2: 1 | B2: Understand the data | C2: Act as a junior data analyst. I have an Excel dataset with Order ID, Date, Month, City, Product, Units, Unit Price and Revenue. Explain what questions this dataset can answer. Do not claim to have analysed the file unless I attach it. | D2: Check that proposed questions can be answered by columns.
A3: 2 | B3: Write an effective prompt | C3: Act as a retail data analyst. Using my attached Sales Data sheet, report total revenue, total orders and top product by revenue. Present results in a 3-row table and show the calculation logic. Do not invent missing data. | D3: Compare totals with Analysis tab.
A4: 3 | B4: SQL prompting | C4: Write a beginner-friendly MySQL query that calculates revenue by product from a sales table with columns product, units and unit_price. Explain each line and assume revenue = units * unit_price. | D4: Run the query on a properly imported dataset.
A5: 4 | B5: Excel prompting | C5: Suggest the Excel formulas to calculate revenue per order and revenue by month in my workbook. Explain which cells to use and why. | D5: Compare to H2 and monthly SUMIF formulas.
A6: 5 | B6: Insight writing | C6: Based on the monthly revenue values that I paste, write 3 concise business insights. Distinguish observed trends from possible causes. Do not guess reasons that the data cannot establish. | D6: Verify each number, and check assumptions.
A7: 6 | B7: Improving prompts | C7: Critique my prompt for ambiguity, lack of context and missing output requirements. Then rewrite it to be more precise and testable. | D7: Compare initial and improved output.
A8: 7 | B8: Interview preparation | C8: Act as an interviewer for a junior data analyst position. Ask me five questions about my Excel and ChatGPT sales analysis project, one at a time. Then suggest improvements to my answers. | D8: Explain what you personally built and verified.

Sheet Pivot-Table
A1: Create your first Pivot Table
A3: Date | B3: Month | C3: City | D3: Product | E3: Units | F3: Unit Price (£) | G3: Revenue (£) | H3: Sales Performance
A4: 46025 | B4: 46023 | C4: Oxford | D4: Mouse | E4: 3 | F4: 25 | G4: =E4*F4 -> 75 | H4: =IF(G4>=1000,"High Sales","Low Sales") -> Low Sales
A5: 46027 | B5: 46023 | C5: Bristol | D5: Keyboard | E5: 4 | F5: 40 | G5: =E5*F5 -> 160 | H5: =IF(G5>=1000,"High Sales","Low Sales") -> Low Sales
A6: 46029 | B6: 46023 | C6: Reading | D6: Laptop | E6: 5 | F6: 850 | G6: =E6*F6 -> 4250 | H6: =IF(G6>=1000,"High Sales","Low Sales") -> High Sales
A7: 46031 | B7: 46023 | C7: London | D7: Monitor | E7: 6 | F7: 220 | G7: =E7*F7 -> 1320 | H7: =IF(G7>=1000,"High Sales","Low Sales") -> High Sales
A8: 46033 | B8: 46023 | C8: Oxford | D8: Headphones | E8: 1 | F8: 65 | G8: =E8*F8 -> 65 | H8: =IF(G8>=1000,"High Sales","Low Sales") -> Low Sales
A9: 46035 | B9: 46023 | C9: Bristol | D9: Mouse | E9: 2 | F9: 25 | G9: =E9*F9 -> 50 | H9: =IF(G9>=1000,"High Sales","Low Sales") -> Low Sales
A10: 46037 | B10: 46023 | C10: Reading | D10: Keyboard | E10: 3 | F10: 40 | G10: =E10*F10 -> 120 | H10: =IF(G10>=1000,"High Sales","Low Sales") -> Low Sales
A11: 46039 | B11: 46023 | C11: London | D11: Laptop | E11: 4 | F11: 850 | G11: =E11*F11 -> 3400 | H11: =IF(G11>=1000,"High Sales","Low Sales") -> High Sales
A12: 46041 | B12: 46023 | C12: Oxford | D12: Monitor | E12: 5 | F12: 220 | G12: =E12*F12 -> 1100 | H12: =IF(G12>=1000,"High Sales","Low Sales") -> High Sales
A13: 46043 | B13: 46023 | C13: Bristol | D13: Headphones | E13: 6 | F13: 65 | G13: =E13*F13 -> 390 | H13: =IF(G13>=1000,"High Sales","Low Sales") -> Low Sales
A14: 46076 | B14: 46054 | C14: London | D14: Laptop | E14: 2 | F14: 850 | G14: =E14*F14 -> 1700 | H14: =IF(G14>=1000,"High Sales","Low Sales") -> High Sales
A15: 46078 | B15: 46054 | C15: Oxford | D15: Monitor | E15: 3 | F15: 220 | G15: =E15*F15 -> 660 | H15: =IF(G15>=1000,"High Sales","Low Sales") -> Low Sales
... A63: 46186 | B63: 46174 | C63: Oxford | D63: Headphones | E63: 1 | F63: 65 | G63: =E63*F63 -> 65 | H63: =IF(G63>=1000,"High Sales","Low Sales") -> Low Sales
